import pytest

from middlewared.service_exception import CallError
from middlewared.test.integration.assets.account import user
from middlewared.test.integration.assets.pool import dataset
from middlewared.test.integration.utils import call


@pytest.fixture(scope="module")
def credential():
    credential = call("keychaincredential.create", {
        "name": "key",
        "type": "SSH_KEY_PAIR",
        "attributes": call("keychaincredential.generate_ssh_key_pair"),
    })
    try:
        yield credential
    finally:
        call("keychaincredential.delete", credential["id"])


def test_remote_ssh_semiautomatic_setup_invalid_homedir(credential):
    with user({
        "username": "admin",
        "full_name": "admin",
        "group_create": True,
        "home_create": False,
        "password": "test1234",
    }):
        token = call("auth.generate_token", 600, {}, False)
        with pytest.raises(CallError) as ve:
            call("keychaincredential.remote_ssh_semiautomatic_setup", {
                "name": "localhost",
                "url": "http://localhost",
                "token": token,
                "username": "admin",
                "private_key": credential["id"],
            })

        assert "make sure that home directory for admin user on the remote system exists" in ve.value.errmsg


def test_remote_ssh_semiautomatic_setup_sets_user_attributes(credential):
    with dataset("unpriv_homedir") as homedir:
        with user({
            "username": "unpriv",
            "full_name": "unpriv",
            "group_create": True,
            "home": f"/mnt/{homedir}",
            "password_disabled": True,
            "smb": False,
            "shell": "/usr/sbin/nologin",
        }):
            token = call("auth.generate_token", 600, {}, False)
            connection = call("keychaincredential.remote_ssh_semiautomatic_setup", {
                "name": "localhost",
                "url": "http://localhost",
                "token": token,
                "username": "unpriv",
                "private_key": credential["id"],
            })
            try:
                call("replication.list_datasets", "SSH", connection["id"])
            finally:
                call("keychaincredential.delete", connection["id"])


def test_ssl_certificate_error(credential):
    token = call("auth.generate_token", 600, {}, False)
    with pytest.raises(CallError) as ve:
        call("keychaincredential.remote_ssh_semiautomatic_setup", {
            "name": "localhost",
            # Should fail on default self-signed certificate
            "url": "https://localhost",
            "token": token,
            "private_key": credential["id"],
        })

    assert ve.value.errno == CallError.ESSLCERTVERIFICATIONERROR


def test_ignore_ssl_certificate_error(credential):
    token = call("auth.generate_token", 600, {}, False)
    connection = call("keychaincredential.remote_ssh_semiautomatic_setup", {
        "name": "localhost",
        "url": "https://localhost",
        "verify_ssl": False,
        "token": token,
        "private_key": credential["id"],
    })
    call("keychaincredential.delete", connection["id"])
